Workbook

Sheet Exec Summary
A1: DMT Stormwater Resilience - Exec Summary
A2: Region | B2: Al Ain
A3: Configurable deadline
B4: Deadline_Date >> | C4: =DATE(2027,2,14) -> 46432
A6: SLIDE 1 - Region Overview
A7: Overview & Criticality
A8: Metric | B8: Count | C8: % of total
A9: Total stormwater hotspots | B9: =COUNTIF(Analysis!$A$4:$A$603,">0") -> 184
A10: Very high | B10: =SUMPRODUCT((UPPER(TRIM(Analysis!$F$4:$F$603))="VERY HIGH")*1) -> 89 | C10: =IF($B$9=0,0,B10/$B$9) -> 0.48369565
A11: High | B11: =SUMPRODUCT((UPPER(TRIM(Analysis!$F$4:$F$603))="HIGH")*1) -> 60 | C11: =IF($B$9=0,0,B11/$B$9) -> 0.32608696
A12: Medium | B12: =SUMPRODUCT((UPPER(TRIM(Analysis!$F$4:$F$603))="MEDIUM")*1) -> 32 | C12: =IF($B$9=0,0,B12/$B$9) -> 0.17391304
A13: Low | B13: =SUMPRODUCT((UPPER(TRIM(Analysis!$F$4:$F$603))="LOW")*1) -> 3 | C13: =IF($B$9=0,0,B13/$B$9) -> 0.016304348
A14: Highly critical (Very High + High) | B14: =(COUNTIF(Analysis!$F$4:$F$603,"Very High*")+COUNTIF(Analysis!$F$4:$F$603,"High*")) -> 149 | C14: =IF($B$9=0,0,B14/$B$9) -> 0.80978261
A15: Critical (Medium + Low) | B15: =(COUNTIF(Analysis!$F$4:$F$603,"Medium*")+COUNTIF(Analysis!$F$4:$F$603,"Low*")) -> 35 | C15: =IF($B$9=0,0,B15/$B$9) -> 0.19021739
A17: Coverage (who owns the hotspot area)
A18: Coverage | B18: Count | C18: % of total
A19: Covered by Municipality (developer blank/No) | B19: =COUNTIF(Analysis!$BG$4:$BG$603,FALSE()) -> 0 | C19: =IF(COUNTIF(Analysis!$A$4:$A$603,">0")=0,0,B19/COUNTIF(Analysis!$A$4:$A$603,">0")) -> 0
A20: Covered by Private Entities / Developers | B20: =COUNTIF(Analysis!$BG$4:$BG$603,TRUE()) -> 184 | C20: =IF(COUNTIF(Analysis!$A$4:$A$603,">0")=0,0,B20/COUNTIF(Analysis!$A$4:$A$603,">0")) -> 1
A22: Root cause
A23: Root cause | B23: Count | C23: % of total
A24: Topography & Road Engineering | B24: =COUNTIF(Analysis!$BH$4:$BH$603,"Topography & Road Engineering") -> 11 | C24: =IF(COUNTIF(Analysis!$A$4:$A$603,">0")=0,0,B24/COUNTIF(Analysis!$A$4:$A$603,">0")) -> 0.059782609
A25: Inadequate Design Capacity | B25: =COUNTIF(Analysis!$BH$4:$BH$603,"Inadequate Design Capacity") -> 139 | C25: =IF(COUNTIF(Analysis!$A$4:$A$603,">0")=0,0,B25/COUNTIF(Analysis!$A$4:$A$603,">0")) -> 0.75543478
A26: Absence of Drainage Network | B26: =COUNTIF(Analysis!$BH$4:$BH$603,"Absence of Drainage Network") -> 34 | C26: =IF(COUNTIF(Analysis!$A$4:$A$603,">0")=0,0,B26/COUNTIF(Analysis!$A$4:$A$603,">0")) -> 0.18478261
A27: Unmapped / CHECK | B27: =COUNTIF(Analysis!$BH$4:$BH$603,"CHECK - map manually") -> 0 | C27: =IF(COUNTIF(Analysis!$A$4:$A$603,">0")=0,0,B27/COUNTIF(Analysis!$A$4:$A$603,">0")) -> 0
A29: Other Metrics
A30: Metric | B30: Count
A31: On existing stormwater network (Yes) | B31: =COUNTIF(Analysis!$I$4:$I$603,"Yes") -> 139
A32: Not on network (No) | B32: =COUNTIF(Analysis!$I$4:$I$603,"No") -> 45
A33: Duplicate Hotspot IDs (should be 0) | B33: =SUMPRODUCT((Analysis!$A$4:$A$603<>"")*(COUNTIF(Analysis!$A$4:$A$603,Analysis!$A$4:$A$603)>1)) -> 0
A34: ADM/IDD pond-scope overlaps flagged | B34: =SUMPRODUCT((Analysis!$A$4:$A$603<>"")*(Analysis!$AE$4:$AE$603>0)*((ISNUMBER(SEARCH("pond",(Analysis!$AN$4:$AN$603&" "&Analysis!$AO$4:$AO$603)))+ISNUMBER(SEARCH("retention",(Analysis!$AN$4:$AN$603&" "&Analysis!$AO$4:$AO$603)))+ISNUMBER(SEARCH("detention",(Analysis!$AN$4:$AN$603&" "&Analysis!$AO$4:$AO$603))))>0)) -> 0
A36: SLIDE 2 - Municipality Emergency Response Plan
A37: AAM Daily Rate
A38: Metric | B38: Highly Critical | C38: Critical | D38: Total
A39: Hotspots covered | B39: =(COUNTIF(Analysis!$F$4:$F$603,"Very High*")+COUNTIF(Analysis!$F$4:$F$603,"High*")) -> 149 | C39: =(COUNTIF(Analysis!$F$4:$F$603,"Medium*")+COUNTIF(Analysis!$F$4:$F$603,"Low*")) -> 35 | D39: =COUNTIF(Analysis!$A$4:$A$603,">0") -> 184
A40: Manpower (headcount) | B40: =(SUMIFS(Analysis!$L$4:$L$603,Analysis!$F$4:$F$603,"Very High*")+SUMIFS(Analysis!$L$4:$L$603,Analysis!$F$4:$F$603,"High*")) -> 0 | C40: =(SUMIFS(Analysis!$L$4:$L$603,Analysis!$F$4:$F$603,"Medium*")+SUMIFS(Analysis!$L$4:$L$603,Analysis!$F$4:$F$603,"Low*")) -> 0 | D40: =SUM(Analysis!$L$4:$L$603) -> 0
A41: Pumps (qty) | B41: =(SUMIFS(Analysis!$P$4:$P$603,Analysis!$F$4:$F$603,"Very High*")+SUMIFS(Analysis!$P$4:$P$603,Analysis!$F$4:$F$603,"High*")) -> 35 | C41: =(SUMIFS(Analysis!$P$4:$P$603,Analysis!$F$4:$F$603,"Medium*")+SUMIFS(Analysis!$P$4:$P$603,Analysis!$F$4:$F$603,"Low*")) -> 12 | D41: =SUM(Analysis!$P$4:$P$603) -> 47 | E41: =D41+D43 -> 56
A42: Tankers (qty) | B42: =(SUMIFS(Analysis!$AA$4:$AA$603,Analysis!$F$4:$F$603,"Very High*")+SUMIFS(Analysis!$AA$4:$AA$603,Analysis!$F$4:$F$603,"High*")) -> 138 | C42: =(SUMIFS(Analysis!$AA$4:$AA$603,Analysis!$F$4:$F$603,"Medium*")+SUMIFS(Analysis!$AA$4:$AA$603,Analysis!$F$4:$F$603,"Low*")) -> 32 | D42: =SUM(Analysis!$AA$4:$AA$603) -> 170 | E42: =D42+D44 -> 190
A43: Additional pumps (qty) | B43: 9 | D43: 9
A44: Additional tankers (qty) | B44: 20 | D44: 20
A45: Manpower budget (AED) | B45: =(SUMIFS(Analysis!$O$4:$O$603,Analysis!$F$4:$F$603,"Very High*")+SUMIFS(Analysis!$O$4:$O$603,Analysis!$F$4:$F$603,"High*")) -> 0 | C45: =(SUMIFS(Analysis!$O$4:$O$603,Analysis!$F$4:$F$603,"Medium*")+SUMIFS(Analysis!$O$4:$O$603,Analysis!$F$4:$F$603,"Low*")) -> 0 | D45: =SUM(Analysis!$O$4:$O$603) -> 0
...

Sheet Analysis
L1: Municipality Emergency Response Plan A For storm events up to a 1-in-10-year event: Very high Criticality hotspot: <2h | High criticality hotspot: <4h | Medium criticality hotspot: <10h | Low criticality hotspot: >10h | AG1: Municipality Emergency Response Plan B For storm events exceeding a 1-in-10-year event: Very high Criticality hotspot: <4h | High criticality hotspot: <6h | Medium criticality hotspot: <10h | Low criticality hotspot: >10h | AM1: IDD Intervention Plan
AM2: Select Yes or No | AN2: Select one: Critical Infrastructure, Detailed Design, Fast-Track, or Quick Win | AO2: Provide the primary solution such as inlet, pipe, Upgrade to Catchment , Pond / Spillway, etc | AP2: Select one: Permanent, Interim, or Temporary | AQ2: Please specify if additional budget is required for this hotspot (Yes/No) | AR2: Provide the requested budget for each applicable hotspot. If a single project spans multiple hotspots, list the budget only once under the primary hotspot. For all other covered hotspot entries, replace the budget with: "Included in Hotspot #X budget." | AS2: Provide the current rainfall design event, including the return period | AT2: Provide the existing network’s technical or hydraulic capacit | AU2: Provide the future or target rainfall design event, including the return period | AV2: Provide the future or target network capacity after the planned intervention | AW2: Provide the estimated floodwater volume managed by network after intervention | AX2: Provide the expected number of hours required for floodwater to recede after intervention | AY2: Revise the planned mobilization date | AZ2: Revise the planned completion date | BA2: Select one: Contractor Design phase, Parsons Verification Phase, IDAS Review Phase, Municipality Permitting Phase, Implementation phase, Hand Over Phase | BB2: Select Yes or No. Enter Yes only after formal approval has been issued. | BC2: Provide the actual mobilization date (only after actual mobilization) | BD2: Provide the actual completion date (only after actual completion) | BE2: Select one: Not Started, On Track, Delayed, or Completed | BF2: Provide the full name of the accountable IDD owner.
A3: Hotspot_ID | B3: Hotspot_Area | C3: Hotspot_Location | D3: Latitude | E3: Longitude | F3: Criticality | G3: Developer_Private_Area | H3: Developer Name | I3: Network_Available | J3: Root_Cause | K3: Root_Cause_Details | L3: Manpower_Qty | M3: Manpower Active-duty AED | N3: Manpower Standby AED | O3: Total Manpower_Budget_AED | P3: Pumps_Qty | Q3: Diesel Pump 12 inch Qty | R3: Diesel Pump 8 inch Qty | S3: Diesel Pump 6 inch Qty | T3: Diesel Pump 12 inch AED/Day | U3: Diesel Pump 8 inch AED/Day | V3: Diesel Pump 6 inch AED/Day | W3: Total Pump Daily Rate | X3: Total Pump Active Duty AED2 | Y3: Total Pump Standby AED | Z3: Pumps_Budget_AED | AA3: Tankers_Qty | AB3: Tankers_Budget_AED | AC3: Concrete_Barrier_AED | AD3: Sand_Barrier_AED | AE3: Detention_Ponds_AED | AF3: Collection_Chamber_AED | AG3: Manpower_Qty2 | AH3: Manpower_Budget_AED3 | AI3: Pumps_Qty4 | AJ3: Pumps_Budget_AED5 | AK3: Tankers_Qty6 | AL3: Tankers_Budget_AED7 | AM3: IDD Interventoin Planned | AN3: IDD_Design_Category | AO3: Design Solution | AP3: Type of Intervention | AQ3: Additional Budget Requirment | AR3: Additional Budget Requested | AS3: Hotspot Network Rain Design Event (Current) | AT3: Hotspot Network Design Technical Capacity (Current) | AU3: Hotspot Network Rain Design Event (Future) | AV3: Hotspot Network Design Technical Capacity (Future) | AW3: Flood Volume Capacity after Intervention | AX3: Associated recovery time after intervention | AY3: Planned_IDD_Mobilization_Date | AZ3: Planned_IDD_Completion_Date | BA3: Project Stage | BB3: Approval from IDAS secured (Yes/No) | BC3: Actual_Mobilization_Date | BD3: Actual_Completion_Date | BE3: Intervention status | BF3: IDD_Owner_Name | BG3: Is_Private_Developer | BH3: Root_Cause_Category | BI3: IDD_Covered | BJ3: IDD_Completion_Date2 | BK3: IDD_Timeline_Status
A4: 1 | B4: Al Aamerah & Al Sad & Al Salamat | C4: Al Rifaa, Al Aamerah | D4: 24.245658 | E4: 55.574298 | F4: Very High | G4: Applicable with (AACM) | I4: No | J4: Absence of Drainage Network | K4: the accumulated water will be removed by a tanker and discharged at the nearest pond or another disposal location | P4: 6 | Z4: 30000 | AA4: 30 | AB4: 150000 | AM4: No | AN4: Based on future design | AO4: Based on future design | AP4: Permenent | AQ4: No | AR4: - | AS4: No network | AT4: N/A | AU4: Based on future design | AV4: Based on future design | AW4: the information will be provided by end of next week | AX4: the information will be provided by end of next week | AY4: future project | AZ4: future project | BA4: future project | BB4: No | BC4: - | BD4: - | BE4: Not Started | BF4: AAI | BG4: =IF(A4="","",AND(TRIM(G4&"")<>"",UPPER(TRIM(G4&""))<>"NO")) -> TRUE | BH4: =IF(J4="","",IF(ISNUMBER(SEARCH("absen",J4)),"Absence of Drainage Network",IF(OR(ISNUMBER(SEARCH("design",J4)),ISNUMBER(SEARCH("capacity",J4))),"Inadequate Design Capacity",IF(OR(ISNUMBER(SEARCH("upgrade",J4)),ISNUMBER(SEARCH("network",J4)),ISNUMBER(SEARCH("topog",J4)),ISNUMBER(SEARCH("road",J4))),"Topography & Road Engineering","CHECK - map manually")))) -> Absence of Drainage Network | BI4: =IF(A4="","",AND(UPPER(TRIM(BF4&""))="IDD",OR(TRIM(AN4&"")<>"",TRIM(AY4&"")<>"",TRIM(AZ4&"")<>""))) -> FALSE | BJ4: =IF(A4="","",IF(ISNUMBER(AZ4),AZ4,"CLIENT INPUT REQUIRED")) -> CLIENT INPUT REQUIRED | BK4: =IF(A4="","",IF(BI4<>TRUE(),"No specific plan",IF(ISNUMBER(BJ4),IF(BJ4<'Exec Summary'!$C$4,"Resolved before Feb 2027","Resolved after Feb 2027"),"CLIENT INPUT REQUIRED"))) -> No specific plan
A5: 2 | B5: Al Aamerah & Al Sad & Al Salamat | C5: 34 Ramlat Al Khadar St, Al Aamerah - Al Samar | D5: 24.238327 | E5: 55.551995 | F5: Very High | G5: Applicable with (AACM) | I5: Yes | J5: Inadequate Design Capacity | K5: Existing or nearby drainage arrangements at 34 Ramlat Al Khadar St, Al Aamerah - Al Samar require pumping support during storm events, indicating insufficient conveyance/storage capacity for peak runoff. | AM5: Yes | AN5: Upgrade Network | AO5: Upgrade Network | AP5: Permenent | AQ5: No | AR5: - | AS5: 1:2 | AT5: 23mm depth for 24hr | AU5: 1:5 | AV5: 47mm depth for 24hr | AW5: the information will be provided by end of next week | AX5: the information will be provided by end of next week | AY5: 46327 | AZ5: 46722 | BA5: Design phase | BB5: Yes | BC5: - | BD5: - | BE5: Not Started | BF5: AAI | BG5: =IF(A5="","",AND(TRIM(G5&"")<>"",UPPER(TRIM(G5&""))<>"NO")) -> TRUE | BH5: =IF(J5="","",IF(ISNUMBER(SEARCH("absen",J5)),"Absence of Drainage Network",IF(OR(ISNUMBER(SEARCH("design",J5)),ISNUMBER(SEARCH("capacity",J5))),"Inadequate Design Capacity",IF(OR(ISNUMBER(SEARCH("upgrade",J5)),ISNUMBER(SEARCH("network",J5)),ISNUMBER(SEARCH("topog",J5)),ISNUMBER(SEARCH("road",J5))),"Topography & Road Engineering","CHECK - map manually")))) -> Inadequate Design Capacity | BI5: =IF(A5="","",AND(UPPER(TRIM(BF5&""))="IDD",OR(TRIM(AN5&"")<>"",TRIM(AY5&"")<>"",TRIM(AZ5&"")<>""))) -> FALSE | BJ5: =IF(A5="","",IF(ISNUMBER(AZ5),AZ5,"CLIENT INPUT REQUIRED")) -> 46722 | BK5: =IF(A5="","",IF(BI5<>TRUE(),"No specific plan",IF(ISNUMBER(BJ5),IF(BJ5<'Exec Summary'!$C$4,"Resolved before Feb 2027","Resolved after Feb 2027"),"CLIENT INPUT REQUIRED"))) -> No specific plan
A6: 3 | B6: Al Aamerah & Al Sad & Al Salamat | C6: Al Samar, Al Aamerah | D6: 24.234745 | E6: 55.550541 | F6: Very High | G6: Applicable with (AACM) | I6: Yes | J6: Inadequate Design Capacity | K6: Existing or nearby drainage arrangements at Al Samar, Al Aamerah require pumping support during storm events, indicating insufficient conveyance/storage capacity for peak runoff. | AM6: Yes | AN6: Upgrade Network | AO6: Upgrade Network | AP6: Permenent | AQ6: No | AR6: - | AS6: 1:2 | AT6: 23mm depth for 24hr | AU6: 1:5 | AV6: 47mm depth for 24hr | AW6: the information will be provided by end of next week | AX6: the information will be provided by end of next week | AY6: 46327 | AZ6: 46722 | BA6: Design phase | BB6: Yes | BC6: - | BD6: - | BE6: Not Started | BF6: AAI | BG6: =IF(A6="","",AND(TRIM(G6&"")<>"",UPPER(TRIM(G6&""))<>"NO")) -> TRUE | BH6: =IF(J6="","",IF(ISNUMBER(SEARCH("absen",J6)),"Absence of Drainage Network",IF(OR(ISNUMBER(SEARCH("design",J6)),ISNUMBER(SEARCH("capacity",J6))),"Inadequate Design Capacity",IF(OR(ISNUMBER(SEARCH("upgrade",J6)),ISNUMBER(SEARCH("network",J6)),ISNUMBER(SEARCH("topog",J6)),ISNUMBER(SEARCH("road",J6))),"Topography & Road Engineering","CHECK - map manually")))) -> Inadequate Design Capacity | BI6: =IF(A6="","",AND(UPPER(TRIM(BF6&""))="IDD",OR(TRIM(AN6&"")<>"",TRIM(AY6&"")<>"",TRIM(AZ6&"")<>""))) -> FALSE | BJ6: =IF(A6="","",IF(ISNUMBER(AZ6),AZ6,"CLIENT INPUT REQUIRED")) -> 46722 | BK6: =IF(A6="","",IF(BI6<>TRUE(),"No specific plan",IF(ISNUMBER(BJ6),IF(BJ6<'Exec Summary'!$C$4,"Resolved before Feb 2027","Resolved after Feb 2027"),"CLIENT INPUT REQUIRED"))) -> No specific plan
A7: 4 | B7: Al Aamerah & Al Sad & Al Salamat | C7: Wadi Al Fayah St, Al Sad - Ramlat Al Saad | D7: 24.219743 | E7: 55.501417 | F7: Very High | G7: Applicable with (AACM) | I7: Yes | J7: Inadequate Design Capacity | K7: Existing or nearby drainage arrangements at Wadi Al Fayah St, Al Sad - Ramlat Al Saad require pumping support during storm events, indicating insufficient conveyance/storage capacity for peak runoff. | AM7: No | AN7: Based on future design | AO7: Based on future design | AP7: Permenent | AQ7: No | AR7: - | AS7: 1:2 | AT7: 23mm depth for 24hr | AU7: Based on future design | AV7: Based on future design | AW7: the information will be provided by end of next week | AX7: the information will be provided by end of next week | AY7: future project | AZ7: future project | BA7: future project | BB7: No | BC7: - | BD7: - | BE7: Not Started | BF7: AAI | BG7: =IF(A7="","",AND(TRIM(G7&"")<>"",UPPER(TRIM(G7&""))<>"NO")) -> TRUE | BH7: =IF(J7="","",IF(ISNUMBER(SEARCH("absen",J7)),"Absence of Drainage Network",IF(OR(ISNUMBER(SEARCH("design",J7)),ISNUMBER(SEARCH("capacity",J7))),"Inadequate Design Capacity",IF(OR(ISNUMBER(SEARCH("upgrade",J7)),ISNUMBER(SEARCH("network",J7)),ISNUMBER(SEARCH("topog",J7)),ISNUMBER(SEARCH("road",J7))),"Topography & Road Engineering","CHECK - map manually")))) -> Inadequate Design Capacity | BI7: =IF(A7="","",AND(UPPER(TRIM(BF7&""))="IDD",OR(TRIM(AN7&"")<>"",TRIM(AY7&"")<>"",TRIM(AZ7&"")<>""))) -> FALSE | BJ7: =IF(A7="","",IF(ISNUMBER(AZ7),AZ7,"CLIENT INPUT REQUIRED")) -> CLIENT INPUT REQUIRED | BK7: =IF(A7="","",IF(BI7<>TRUE(),"No specific plan",IF(ISNUMBER(BJ7),IF(BJ7<'Exec Summary'!$C$4,"Resolved before Feb 2027","Resolved after Feb 2027"),"CLIENT INPUT REQUIRED"))) -> No specific plan
A8: 5 | B8: Al Aamerah & Al Sad & Al Salamat | C8: 28 An Nasr St, Al Salamat - Al Salamat 1 | D8: 24.213406 | E8: 55.590641 | F8: Very High | G8: Applicable with (AACM) | I8: Yes | J8: Inadequate Design Capacity | K8: Existing or nearby drainage arrangements at 28 An Nasr St, Al Salamat - Al Salamat 1 require pumping support during storm events, indicating insufficient conveyance/storage capacity for peak runoff. | AM8: Yes | AN8: Upgrade Network | AO8: Upgrade Network | AP8: Permenent | AQ8: No | AR8: - | AS8: 1:2 | AT8: 23mm depth for 24hr | AU8: 1:5 | AV8: 47mm depth for 24hr | AW8: the information will be provided by end of next week | AX8: the information will be provided by end of next week | AY8: 46327 | AZ8: 46722 | BA8: Design phase | BB8: Yes | BC8: - | BD8: - | BE8: Not Started | BF8: AAI | BG8: =IF(A8="","",AND(TRIM(G8&"")<>"",UPPER(TRIM(G8&""))<>"NO")) -> TRUE | BH8: =IF(J8="","",IF(ISNUMBER(SEARCH("absen",J8)),"Absence of Drainage Network",IF(OR(ISNUMBER(SEARCH("design",J8)),ISNUMBER(SEARCH("capacity",J8))),"Inadequate Design Capacity",IF(OR(ISNUMBER(SEARCH("upgrade",J8)),ISNUMBER(SEARCH("network",J8)),ISNUMBER(SEARCH("topog",J8)),ISNUMBER(SEARCH("road",J8))),"Topography & Road Engineering","CHECK - map manually")))) -> Inadequate Design Capacity | BI8: =IF(A8="","",AND(UPPER(TRIM(BF8&""))="IDD",OR(TRIM(AN8&"")<>"",TRIM(AY8&"")<>"",TRIM(AZ8&"")<>""))) -> FALSE | BJ8: =IF(A8="","",IF(ISNUMBER(AZ8),AZ8,"CLIENT INPUT REQUIRED")) -> 46722 | BK8: =IF(A8="","",IF(BI8<>TRUE(),"No specific plan",IF(ISNUMBER(BJ8),IF(BJ8<'Exec Summary'!$C$4,"Resolved before Feb 2027","Resolved after Feb 2027"),"CLIENT INPUT REQUIRED"))) -> No specific plan
A9: 6 | B9: Al Arad | C9: Sayh Al ʹArad St, Al 'Arad - Al Arad 1 | D9: 23.846971 | E9: 55.529396 | F9: Medium | G9: Applicable with (AACM) | I9: No | J9: Absence of Drainage Network | K9: No effective stormwater connection is evident from the listed intervention at Sayh Al ʹArad St, Al 'Arad - Al Arad 1; response is based on tanker dewatering until a drainage network/permanent solution is available. | P9: 0 | Z9: 0 | AA9: 1 | AB9: 5000 | AM9: No | AN9: Based on future design | AO9: Based on future design | AP9: Permenent | AQ9: No | AR9: - | AS9: No network | AT9: N/A | AU9: Based on future design | AV9: Based on future design | AW9: the information will be provided by end of next week | AX9: the information will be provided by end of next week | AY9: future project | AZ9: future project | BA9: future project | BB9: No | BC9: - | BD9: - | BE9: Not Started | BF9: AAI | BG9: =IF(A9="","",AND(TRIM(G9&"")<>"",UPPER(TRIM(G9&""))<>"NO")) -> TRUE | BH9: =IF(J9="","",IF(ISNUMBER(SEARCH("absen",J9)),"Absence of Drainage Network",IF(OR(ISNUMBER(SEARCH("design",J9)),ISNUMBER(SEARCH("capacity",J9))),"Inadequate Design Capacity",IF(OR(ISNUMBER(SEARCH("upgrade",J9)),ISNUMBER(SEARCH("network",J9)),ISNUMBER(SEARCH("topog",J9)),ISNUMBER(SEARCH("road",J9))),"Topography & Road Engineering","CHECK - map manually")))) -> Absence of Drainage Network | BI9: =IF(A9="","",AND(UPPER(TRIM(BF9&""))="IDD",OR(TRIM(AN9&"")<>"",TRIM(AY9&"")<>"",TRIM(AZ9&"")<>""))) -> FALSE | BJ9: =IF(A9="","",IF(ISNUMBER(AZ9),AZ9,"CLIENT INPUT REQUIRED")) -> CLIENT INPUT REQUIRED | BK9: =IF(A9="","",IF(BI9<>TRUE(),"No specific plan",IF(ISNUMBER(BJ9),IF(BJ9<'Exec Summary'!$C$4,"Resolved before Feb 2027","Resolved after Feb 2027"),"CLIENT INPUT REQUIRED"))) -> No specific plan
A10: 7 | B10: Al Bateen | C10: Ghafat Al Shwaihi, Al Bateen | D10: 24.210464 | E10: 55.635865 | F10: Medium | G10: Applicable with (AACM) | I10: Yes | J10: Inadequate Design Capacity | K10: Existing or nearby drainage arrangements at Ghafat Al Shwaihi, Al Bateen require pumping support during storm events, indicating insufficient conveyance/storage capacity for peak runoff. | P10: 1 | Z10: 5000 | AA10: 1 | AB10: 5000 | AM10: Yes | AN10: Upgrade Network | AO10: Upgrade Network | AP10: Permenent | AQ10: No | AR10: - | AS10: 1:2 | AT10: 23mm depth for 24hr | AU10: 1:5 | AV10: 47mm depth for 24hr | AW10: the information will be provided by end of next week | AX10: the information will be provided by end of next week | AY10: 45658 | AZ10: 46357 | BA10: Implementation phase | BB10: Yes | BC10: 46064 | BD10: 46264 | BE10: Completed | BF10: AAI | BG10: =IF(A10="","",AND(TRIM(G10&"")<>"",UPPER(TRIM(G10&""))<>"NO")) -> TRUE | BH10: =IF(J10="","",IF(ISNUMBER(SEARCH("absen",J10)),"Absence of Drainage Network",IF(OR(ISNUMBER(SEARCH("design",J10)),ISNUMBER(SEARCH("capacity",J10))),"Inadequate Design Capacity",IF(OR(ISNUMBER(SEARCH("upgrade",J10)),ISNUMBER(SEARCH("network",J10)),ISNUMBER(SEARCH("topog",J10)),ISNUMBER(SEARCH("road",J10))),"Topography & Road Engineering","CHECK - map manually")))) -> Inadequate Design Capacity | BI10: =IF(A10="","",AND(UPPER(TRIM(BF10&""))="IDD",OR(TRIM(AN10&"")<>"",TRIM(AY10&"")<>"",TRIM(AZ10&"")<>""))) -> FALSE | BJ10: =IF(A10="","",IF(ISNUMBER(AZ10),AZ10,"CLIENT INPUT REQUIRED")) -> 46357 | BK10: =IF(A10="","",IF(BI10<>TRUE(),"No specific plan",IF(ISNUMBER(BJ10),IF(BJ10<'Exec Summary'!$C$4,"Resolved before Feb 2027","Resolved after Feb 2027"),"CLIENT INPUT REQUIRED"))) -> No specific plan
A11: 8 | B11: Al Bateen | C11: Yaw Sablah St, Al Bateen - Ghafat Al Shwaihi | D11: 24.209828 | E11: 55.626956 | F11: Medium | G11: Applicable with (AACM) | I11: Yes | J11: Inadequate Design Capacity | K11: Existing or nearby drainage arrangements at Yaw Sablah St, Al Bateen - Ghafat Al Shwaihi require pumping support during storm events, indicating insufficient conveyance/storage capacity for peak runoff. | AM11: Yes | AN11: Based on Future Design | AO11: Based on Future Design | AP11: Permenent | AQ11: No | AR11: - | AS11: 1:2 | AT11: 23mm depth for 24hr | AU11: 1:5 | AV11: 47mm depth for 24hr | AW11: the information will be provided by end of next week | AX11: the information will be provided by end of next week | AY11: 46388 | AZ11: 46722 | BA11: Design phase | BB11: Yes | BC11: - | BD11: - | BE11: Not Started | BF11: AAI | BG11: =IF(A11="","",AND(TRIM(G11&"")<>"",UPPER(TRIM(G11&""))<>"NO")) -> TRUE | BH11: =IF(J11="","",IF(ISNUMBER(SEARCH("absen",J11)),"Absence of Drainage Network",IF(OR(ISNUMBER(SEARCH("design",J11)),ISNUMBER(SEARCH("capacity",J11))),"Inadequate Design Capacity",IF(OR(ISNUMBER(SEARCH("upgrade",J11)),ISNUMBER(SEARCH("network",J11)),ISNUMBER(SEARCH("topog",J11)),ISNUMBER(SEARCH("road",J11))),"Topography & Road Engineering","CHECK - map manually")))) -> Inadequate Design Capacity | BI11: =IF(A11="","",AND(UPPER(TRIM(BF11&""))="IDD",OR(TRIM(AN11&"")<>"",TRIM(AY11&"")<>"",TRIM(AZ11&"")<>""))) -> FALSE | BJ11: =IF(A11="","",IF(ISNUMBER(AZ11),AZ11,"CLIENT INPUT REQUIRED")) -> 46722 | BK11: =IF(A11="","",IF(BI11<>TRUE(),"No specific plan",IF(ISNUMBER(BJ11),IF(BJ11<'Exec Summary'!$C$4,"Resolved before Feb 2027","Resolved after Feb 2027"),"CLIENT INPUT REQUIRED"))) -> No specific plan
A12: 9 | B12: Al Bateen | C12: Ghiyout Al Hidayri St, Al Bateen - Ghafat Al Shwaihi | D12: 24.199295 | E12: 55.628214 | F12: Medium | G12: Applicable with (AACM) | I12: Yes | J12: Inadequate Design Capacity | K12: Existing or nearby drainage arrangements at Ghiyout Al Hidayri St, Al Bateen - Ghafat Al Shwaihi require pumping support during storm events, indicating insufficient conveyance/storage capacity for peak runoff. | AM12: Yes | AN12: Upgrade Network | AO12: Upgrade Network | AP12: Permenent | AQ12: No | AR12: - | AS12: 1:2 | AT12: 23mm depth for 24hr | AU12: 1:5 | AV12: 47mm depth for 24hr | AW12: the information will be provided by end of next week | AX12: the information will be provided by end of next week | AY12: 45658 | AZ12: 46357 | BA12: Implementation phase | BB12: Yes | BC12: 46156 | BD12: - | BE12: On Track | BF12: AAI | BG12: =IF(A12="","",AND(TRIM(G12&"")<>"",UPPER(TRIM(G12&""))<>"NO")) -> TRUE | BH12: =IF(J12="","",IF(ISNUMBER(SEARCH("absen",J12)),"Absence of Drainage Network",IF(OR(ISNUMBER(SEARCH("design",J12)),ISNUMBER(SEARCH("capacity",J12))),"Inadequate Design Capacity",IF(OR(ISNUMBER(SEARCH("upgrade",J12)),ISNUMBER(SEARCH("network",J12)),ISNUMBER(SEARCH("topog",J12)),ISNUMBER(SEARCH("road",J12))),"Topography & Road Engineering","CHECK - map manually")))) -> Inadequate Design Capacity | BI12: =IF(A12="","",AND(UPPER(TRIM(BF12&""))="IDD",OR(TRIM(AN12&"")<>"",TRIM(AY12&"")<>"",TRIM(AZ12&"")<>""))) -> FALSE | BJ12: =IF(A12="","",IF(ISNUMBER(AZ12),AZ12,"CLIENT INPUT REQUIRED")) -> 46357 | BK12: =IF(A12="","",IF(BI12<>TRUE(),"No specific plan",IF(ISNUMBER(BJ12),IF(BJ12<'Exec Summary'!$C$4,"Resolved before Feb 2027","Resolved after Feb 2027"),"CLIENT INPUT REQUIRED"))) -> No specific plan
A13: 10 | B13: Al Dhahir & Mezyad & Um Ghafah | C13: Zayed Bin Sultan St, Al Dhahir - Dhaher 1 | D13: 24.064364 | E13: 55.837395 | F13: High | G13: Applicable with (AACM) | I13: No | J13: Absence of Drainage Network | K13: the accumulated water will be removed by a tanker and discharged at the nearest Wadi | P13: 3 | Z13: 15000 | AA13: 4 | AB13: 20000 | AM13: No | AN13: Based on future design | AO13: Based on future design | AP13: Permenent | AQ13: No | AR13: - | AS13: No network | AT13: N/A | AU13: Based on future design | AV13: Based on future design | AW13: the information will be provided by end of next week | AX13: the information will be provided by end of next week | AY13: future project | AZ13: future project | BA13: future project | BB13: No | BC13: - | BD13: - | BE13: Not Started | BF13: AAI | BG13: =IF(A13="","",AND(TRIM(G13&"")<>"",UPPER(TRIM(G13&""))<>"NO")) -> TRUE | BH13: =IF(J13="","",IF(ISNUMBER(SEARCH("absen",J13)),"Absence of Drainage Network",IF(OR(ISNUMBER(SEARCH("design",J13)),ISNUMBER(SEARCH("capacity",J13))),"Inadequate Design Capacity",IF(OR(ISNUMBER(SEARCH("upgrade",J13)),ISNUMBER(SEARCH("network",J13)),ISNUMBER(SEARCH("topog",J13)),ISNUMBER(SEARCH("road",J13))),"Topography & Road Engineering","CHECK - map manually")))) -> Absence of Drainage Network | BI13: =IF(A13="","",AND(UPPER(TRIM(BF13&""))="IDD",OR(TRIM(AN13&"")<>"",TRIM(AY13&"")<>"",TRIM(AZ13&"")<>""))) -> FALSE | BJ13: =IF(A13="","",IF(ISNUMBER(AZ13),AZ13,"CLIENT INPUT REQUIRED")) -> CLIENT INPUT REQUIRED | BK13: =IF(A13="","",IF(BI13<>TRUE(),"No specific plan",IF(ISNUMBER(BJ13),IF(BJ13<'Exec Summary'!$C$4,"Resolved before Feb 2027","Resolved after Feb 2027"),"CLIENT INPUT REQUIRED"))) -> No specific plan
A14: 11 | B14: Al Dhahir & Mezyad & Um Ghafah | C14: Al Barari Mall R/A, Dhaher 3, Al Dhahir | D14: 24.085678 | E14: 55.831987 | F14: High | G14: Applicable with (AACM) | I14: Yes | J14: Inadequate Design Capacity | K14: Existing or nearby drainage arrangements at Al Barari Mall R/A, Dhaher 3, Al Dhahir require pumping support during storm events, indicating insufficient conveyance/storage capacity for peak runoff. | AM14: No | AN14: Based on future design | AO14: Based on future design | AP14: Permenent | AQ14: No | AR14: - | AS14: 1:2 | AT14: 23mm depth for 24hr | AU14: Based on future design | AV14: Based on future design | AW14: the information will be provided by end of next week | AX14: the information will be provided by end of next week | AY14: future project | AZ14: future project | BA14: future project | BB14: No | BC14: - | BD14: - | BE14: Not Started | BF14: AAI | BG14: =IF(A14="","",AND(TRIM(G14&"")<>"",UPPER(TRIM(G14&""))<>"NO")) -> TRUE | BH14: =IF(J14="","",IF(ISNUMBER(SEARCH("absen",J14)),"Absence of Drainage Network",IF(OR(ISNUMBER(SEARCH("design",J14)),ISNUMBER(SEARCH("capacity",J14))),"Inadequate Design Capacity",IF(OR(ISNUMBER(SEARCH("upgrade",J14)),ISNUMBER(SEARCH("network",J14)),ISNUMBER(SEARCH("topog",J14)),ISNUMBER(SEARCH("road",J14))),"Topography & Road Engineering","CHECK - map manually")))) -> Inadequate Design Capacity | BI14: =IF(A14="","",AND(UPPER(TRIM(BF14&""))="IDD",OR(TRIM(AN14&"")<>"",TRIM(AY14&"")<>"",TRIM(AZ14&"")<>""))) -> FALSE | BJ14: =IF(A14="","",IF(ISNUMBER(AZ14),AZ14,"CLIENT INPUT REQUIRED")) -> CLIENT INPUT REQUIRED | BK14: =IF(A14="","",IF(BI14<>TRUE(),"No specific plan",IF(ISNUMBER(BJ14),IF(BJ14<'Exec Summary'!$C$4,"Resolved before Feb 2027","Resolved after Feb 2027"),"CLIENT INPUT REQUIRED"))) -> No specific plan
A15: 12 | B15: Al Dhahir & Mezyad & Um Ghafah | C15: Al Ain City Municipality – Customer Service Center, Mezyad | D15: 24.032824 | E15: 55.844514 | F15: High | G15: Applicable with (AACM) | I15: No | J15: Absence of Drainage Network | K15: the accumulated water will be removed by a tanker and discharged at the nearest Wadi | AM15: No | AN15: Based on future design | AO15: Based on future design | AP15: Permenent | AQ15: No | AR15: - | AS15: No network | AT15: N/A | AU15: Based on future design | AV15: Based on future design | AW15: the information will be provided by end of next week | AX15: the information will be provided by end of next week | AY15: future project | AZ15: future project | BA15: future project | BB15: No | BC15: - | BD15: - | BE15: Not Started | BF15: AAI | BG15: =IF(A15="","",AND(TRIM(G15&"")<>"",UPPER(TRIM(G15&""))<>"NO")) -> TRUE | BH15: =IF(J15="","",IF(ISNUMBER(SEARCH("absen",J15)),"Absence of Drainage Network",IF(OR(ISNUMBER(SEARCH("design",J15)),ISNUMBER(SEARCH("capacity",J15))),"Inadequate Design Capacity",IF(OR(ISNUMBER(SEARCH("upgrade",J15)),ISNUMBER(SEARCH("network",J15)),ISNUMBER(SEARCH("topog",J15)),ISNUMBER(SEARCH("road",J15))),"Topography & Road Engineering","CHECK - map manually")))) -> Absence of Drainage Network | BI15: =IF(A15="","",AND(UPPER(TRIM(BF15&""))="IDD",OR(TRIM(AN15&"")<>"",TRIM(AY15&"")<>"",TRIM(AZ15&"")<>""))) -> FALSE | BJ15: =IF(A15="","",IF(ISNUMBER(AZ15),AZ15,"CLIENT INPUT REQUIRED")) -> CLIENT INPUT REQUIRED | BK15: =IF(A15="","",IF(BI15<>TRUE(),"No specific plan",IF(ISNUMBER(BJ15),IF(BJ15<'Exec Summary'!$C$4,"Resolved before Feb 2027","Resolved after Feb 2027"),"CLIENT INPUT REQUIRED"))) -> No specific plan
A16: 13 | B16: Al Dhahir & Mezyad & Um Ghafah | C16: Zayed Bin Sultan St, Mazyad - Mazyad 2 | D16: 24.036763 | E16: 55.844098 | F16: High | G16: Applicable with (AACM) | I16: Yes | J16: Inadequate Design Capacity | K16: Existing or nearby drainage arrangements at Zayed Bin Sultan St, Mazyad - Mazyad 2 require pumping support during storm events, indicating insufficient conveyance/storage capacity for peak runoff. | AM16: No | AN16: Based on future design | AO16: Based on future design | AP16: Permenent | AQ16: No | AR16: - | AS16: 1:2 | AT16: 23mm depth for 24hr | AU16: Based on future design | AV16: Based on future design | AW16: the information will be provided by end of next week | AX16: the information will be provided by end of next week | AY16: future project | AZ16: future project | BA16: future project | BB16: No | BC16: - | BD16: - | BE16: Not Started | BF16: AAI | BG16: =IF(A16="","",AND(TRIM(G16&"")<>"",UPPER(TRIM(G16&""))<>"NO")) -> TRUE | BH16: =IF(J16="","",IF(ISNUMBER(SEARCH("absen",J16)),"Absence of Drainage Network",IF(OR(ISNUMBER(SEARCH("design",J16)),ISNUMBER(SEARCH("capacity",J16))),"Inadequate Design Capacity",IF(OR(ISNUMBER(SEARCH("upgrade",J16)),ISNUMBER(SEARCH("network",J16)),ISNUMBER(SEARCH("topog",J16)),ISNUMBER(SEARCH("road",J16))),"Topography & Road Engineering","CHECK - map manually")))) -> Inadequate Design Capacity | BI16: =IF(A16="","",AND(UPPER(TRIM(BF16&""))="IDD",OR(TRIM(AN16&"")<>"",TRIM(AY16&"")<>"",TRIM(AZ16&"")<>""))) -> FALSE | BJ16: =IF(A16="","",IF(ISNUMBER(AZ16),AZ16,"CLIENT INPUT REQUIRED")) -> CLIENT INPUT REQUIRED | BK16: =IF(A16="","",IF(BI16<>TRUE(),"No specific plan",IF(ISNUMBER(BJ16),IF(BJ16<'Exec Summary'!$C$4,"Resolved before Feb 2027","Resolved after Feb 2027"),"CLIENT INPUT REQUIRED"))) -> No specific plan
A17: 14 | B17: Al Dhahir & Mezyad & Um Ghafah | C17: Al Muraikhat, Um Ghafah | D17: 24.091098 | E17: 55.908138 | F17: High | G17: Applicable with (AACM) | I17: Yes | J17: Inadequate Design Capacity | K17: Existing or nearby drainage arrangements at Al Muraikhat, Um Ghafah require pumping support during storm events, indicating insufficient conveyance/storage capacity for peak runoff. | AM17: No | AN17: Based on future design | AO17: Based on future design | AP17: Permenent | AQ17: No | AR17: - | AS17: 1:2 | AT17: 23mm depth for 24hr | AU17: Based on future design | AV17: Based on future design | AW17: the information will be provided by end of next week | AX17: the information will be provided by end of next week | AY17: future project | AZ17: future project | BA17: future project | BB17: No | BC17: - | BD17: - | BE17: Not Started | BF17: AAI | BG17: =IF(A17="","",AND(TRIM(G17&"")<>"",UPPER(TRIM(G17&""))<>"NO")) -> TRUE | BH17: =IF(J17="","",IF(ISNUMBER(SEARCH("absen",J17)),"Absence of Drainage Network",IF(OR(ISNUMBER(SEARCH("design",J17)),ISNUMBER(SEARCH("capacity",J17))),"Inadequate Design Capacity",IF(OR(ISNUMBER(SEARCH("upgrade",J17)),ISNUMBER(SEARCH("network",J17)),ISNUMBER(SEARCH("topog",J17)),ISNUMBER(SEARCH("road",J17))),"Topography & Road Engineering","CHECK - map manually")))) -> Inadequate Design Capacity | BI17: =IF(A17="","",AND(UPPER(TRIM(BF17&""))="IDD",OR(TRIM(AN17&"")<>"",TRIM(AY17&"")<>"",TRIM(AZ17&"")<>""))) -> FALSE | BJ17: =IF(A17="","",IF(ISNUMBER(AZ17),AZ17,"CLIENT INPUT REQUIRED")) -> CLIENT INPUT REQUIRED | BK17: =IF(A17="","",IF(BI17<>TRUE(),"No specific plan",IF(ISNUMBER(BJ17),IF(BJ17<'Exec Summary'!$C$4,"Resolved before Feb 2027","Resolved after Feb 2027"),"CLIENT INPUT REQUIRED"))) -> No specific plan
A18: 15 | B18: Al Faqaa | C18: Al Ain - Dubai Rd, Al Faqaa | D18: 24.686555 | E18: 55.641832 | F18: High | G18: Applicable with (AACM) | I18: No | J18: Absence of Drainage Network | K18: the accumulated water will be removed by a tanker and discharged at the nearest Wadi | P18: 0 | Z18: 0 | AA18: 1 | AB18: 5000 | AM18: Yes | AN18: Pond/Side slope protection | AO18: Pond/Side slope protection | AP18: Permenent | AQ18: No | AR18: - | AS18: 1:2 | AT18: 23mm depth for 24hr | AU18: 1:50 | AV18: 105mm depth for 24hr | AW18: the information will be provided by end of next week | AX18: the information will be provided by end of next week | AY18: 46327 | AZ18: 46722 | BA18: Design phase | BB18: Yes | BC18: - | BD18: - | BE18: Not Started | BF18: AAI | BG18: =IF(A18="","",AND(TRIM(G18&"")<>"",UPPER(TRIM(G18&""))<>"NO")) -> TRUE | BH18: =IF(J18="","",IF(ISNUMBER(SEARCH("absen",J18)),"Absence of Drainage Network",IF(OR(ISNUMBER(SEARCH("design",J18)),ISNUMBER(SEARCH("capacity",J18))),"Inadequate Design Capacity",IF(OR(ISNUMBER(SEARCH("upgrade",J18)),ISNUMBER(SEARCH("network",J18)),ISNUMBER(SEARCH("topog",J18)),ISNUMBER(SEARCH("road",J18))),"Topography & Road Engineering","CHECK - map manually")))) -> Absence of Drainage Network | BI18: =IF(A18="","",AND(UPPER(TRIM(BF18&""))="IDD",OR(TRIM(AN18&"")<>"",TRIM(AY18&"")<>"",TRIM(AZ18&"")<>""))) -> FALSE | BJ18: =IF(A18="","",IF(ISNUMBER(AZ18),AZ18,"CLIENT INPUT REQUIRED")) -> 46722 | BK18: =IF(A18="","",IF(BI18<>TRUE(),"No specific plan",IF(ISNUMBER(BJ18),IF(BJ18<'Exec Summary'!$C$4,"Resolved before Feb 2027","Resolved after Feb 2027"),"CLIENT INPUT REQUIRED"))) -> No specific plan
A19: 16 | B19: Al Faqaa | C19: Dulaymah 1, Al Fagaa | D19: 24.693579 | E19: 55.612559 | F19: High | G19: Applicable with (AACM) | I19: No | J19: Absence of Drainage Network | K19: the accumulated water will be removed by a tanker and discharged at the nearest pond or another disposal location | AM19: No | AN19: Based on future design | AO19: Based on future design | AP19: Permenent | AQ19: No | AR19: - | AS19: No network | AT19: N/A | AU19: Based on future design | AV19: Based on future design | AW19: the information will be provided by end of next week | AX19: the information will be provided by end of next week | AY19: future project | AZ19: future project | BA19: future project | BB19: No | BC19: - | BD19: - | BE19: Not Started | BF19: AAI | BG19: =IF(A19="","",AND(TRIM(G19&"")<>"",UPPER(TRIM(G19&""))<>"NO")) -> TRUE | BH19: =IF(J19="","",IF(ISNUMBER(SEARCH("absen",J19)),"Absence of Drainage Network",IF(OR(ISNUMBER(SEARCH("design",J19)),ISNUMBER(SEARCH("capacity",J19))),"Inadequate Design Capacity",IF(OR(ISNUMBER(SEARCH("upgrade",J19)),ISNUMBER(SEARCH("network",J19)),ISNUMBER(SEARCH("topog",J19)),ISNUMBER(SEARCH("road",J19))),"Topography & Road Engineering","CHECK - map manually")))) -> Absence of Drainage Network | BI19: =IF(A19="","",AND(UPPER(TRIM(BF19&""))="IDD",OR(TRIM(AN19&"")<>"",TRIM(AY19&"")<>"",TRIM(AZ19&"")<>""))) -> FALSE | BJ19: =IF(A19="","",IF(ISNUMBER(AZ19),AZ19,"CLIENT INPUT REQUIRED")) -> CLIENT INPUT REQUIRED | BK19: =IF(A19="","",IF(BI19<>TRUE(),"No specific plan",IF(ISNUMBER(BJ19),IF(BJ19<'Exec Summary'!$C$4,"Resolved before Feb 2027","Resolved after Feb 2027"),"CLIENT INPUT REQUIRED"))) -> No specific plan
A20: 17 | B20: Al Rawdah Al Sharqiyah - Al Ifaz & Al Ghireebah | C20: 19-7 Al Sofouh St, Al Rawdah Al Sharqiyah - Al Ifaz | D20: 24.155127 | E20: 55.658008 | F20: High | G20: Applicable with (AACM) | I20: Yes | J20: Inadequate Design Capacity | K20: Existing or nearby drainage arrangements at 19-7 Al Sofouh St, Al Rawdah Al Sharqiyah - Al Ifaz require pumping support during storm events, indicating insufficient conveyance/storage capacity for peak runoff. | P20: 0 | Z20: 0 | AA20: 1 | AB20: 5000 | AM20: No | AN20: Based on future design | AO20: Based on future design | AP20: Permenent | AQ20: No | AR20: - | AS20: 1:2 | AT20: 23mm depth for 24hr | AU20: Based on future design | AV20: Based on future design | AW20: the information will be provided by end of next week | AX20: the information will be provided by end of next week | AY20: future project | AZ20: future project | BA20: future project | BB20: No | BC20: - | BD20: - | BE20: Not Started | BF20: AAI | BG20: =IF(A20="","",AND(TRIM(G20&"")<>"",UPPER(TRIM(G20&""))<>"NO")) -> TRUE | BH20: =IF(J20="","",IF(ISNUMBER(SEARCH("absen",J20)),"Absence of Drainage Network",IF(OR(ISNUMBER(SEARCH("design",J20)),ISNUMBER(SEARCH("capacity",J20))),"Inadequate Design Capacity",IF(OR(ISNUMBER(SEARCH("upgrade",J20)),ISNUMBER(SEARCH("network",J20)),ISNUMBER(SEARCH("topog",J20)),ISNUMBER(SEARCH("road",J20))),"Topography & Road Engineering","CHECK - map manually")))) -> Inadequate Design Capacity | BI20: =IF(A20="","",AND(UPPER(TRIM(BF20&""))="IDD",OR(TRIM(AN20&"")<>"",TRIM(AY20&"")<>"",TRIM(AZ20&"")<>""))) -> FALSE | BJ20: =IF(A20="","",IF(ISNUMBER(AZ20),AZ20,"CLIENT INPUT REQUIRED")) -> CLIENT INPUT REQUIRED | BK20: =IF(A20="","",IF(BI20<>TRUE(),"No specific plan",IF(ISNUMBER(BJ20),IF(BJ20<'Exec Summary'!$C$4,"Resolved before Feb 2027","Resolved after Feb 2027"),"CLIENT INPUT REQUIRED"))) -> No specific plan
A21: 18 | B21: Al Rawdah Al Sharqiyah - Al Ifaz & Al Ghireebah | C21: Al Ifaz, Al Rawdah Al Sharqiyah | D21: 24.162986 | E21: 55.654951 | F21: Very High | G21: Applicable with (AACM) | I21: No | J21: Absence of Drainage Network | K21: No effective stormwater connection is evident from the listed intervention at Al Ifaz, Al Rawdah Al Sharqiyah; response is based on tanker dewatering until a drainage network/permanent solution is available. Discharge point is nearest Wadi | AM21: No | AN21: Based on future design | AO21: Based on future design | AP21: Permenent | AQ21: No | AR21: - | AS21: No network | AT21: N/A | AU21: Based on future design | AV21: Based on future design | AW21: the information will be provided by end of next week | AX21: the information will be provided by end of next week | AY21: future project | AZ21: future project | BA21: future project | BB21: No | BC21: - | BD21: - | BE21: Not Started | BF21: AAI | BG21: =IF(A21="","",AND(TRIM(G21&"")<>"",UPPER(TRIM(G21&""))<>"NO")) -> TRUE | BH21: =IF(J21="","",IF(ISNUMBER(SEARCH("absen",J21)),"Absence of Drainage Network",IF(OR(ISNUMBER(SEARCH("design",J21)),ISNUMBER(SEARCH("capacity",J21))),"Inadequate Design Capacity",IF(OR(ISNUMBER(SEARCH("upgrade",J21)),ISNUMBER(SEARCH("network",J21)),ISNUMBER(SEARCH("topog",J21)),ISNUMBER(SEARCH("road",J21))),"Topography & Road Engineering","CHECK - map manually")))) -> Absence of Drainage Network | BI21: =IF(A21="","",AND(UPPER(TRIM(BF21&""))="IDD",OR(TRIM(AN21&"")<>"",TRIM(AY21&"")<>"",TRIM(AZ21&"")<>""))) -> FALSE | BJ21: =IF(A21="","",IF(ISNUMBER(AZ21),AZ21,"CLIENT INPUT REQUIRED")) -> CLIENT INPUT REQUIRED | BK21: =IF(A21="","",IF(BI21<>TRUE(),"No specific plan",IF(ISNUMBER(BJ21),IF(BJ21<'Exec Summary'!$C$4,"Resolved before Feb 2027","Resolved after Feb 2027"),"CLIENT INPUT REQUIRED"))) -> No specific plan
A22: 19 | B22: Al Fou'ah | C22: Al Ain - Dubai Rd, Al Nabbagh – Sibeitah Tahnoun Bin Mohammed Al Nhayan Rd. | D22: 24.346862 | E22: 55.777772 | F22: Medium | G22: Applicable with (AACM) | I22: Yes | J22: Inadequate Design Capacity | K22: Existing or nearby drainage arrangements at Al Ain - Dubai Rd, Al Nabbagh – Sibeitah Tahnoun Bin Mohammed Al Nhayan Rd. require pumping support during storm events, indicating insufficient conveyance/storage capacity for peak runoff. | P22: 0 | Z22: 0 | AA22: 2 | AB22: 10000 | AM22: Yes | AN22: Upgrade Underpass drainage system | AO22: Upgrade Underpass drainage system | AP22: Permenent | AQ22: No | AR22: - | AS22: 1:2 | AT22: 23mm depth for 24hr | AU22: 1:50 | AV22: 105mm depth for 24hr | AW22: the information will be provided by end of next week | AX22: the information will be provided by end of next week | AY22: 46419 | AZ22: 46753 | BA22: Design phase | BB22: Yes | BC22: - | BD22: - | BE22: Not Started | BF22: AAI | BG22: =IF(A22="","",AND(TRIM(G22&"")<>"",UPPER(TRIM(G22&""))<>"NO")) -> TRUE | BH22: =IF(J22="","",IF(ISNUMBER(SEARCH("absen",J22)),"Absence of Drainage Network",IF(OR(ISNUMBER(SEARCH("design",J22)),ISNUMBER(SEARCH("capacity",J22))),"Inadequate Design Capacity",IF(OR(ISNUMBER(SEARCH("upgrade",J22)),ISNUMBER(SEARCH("network",J22)),ISNUMBER(SEARCH("topog",J22)),ISNUMBER(SEARCH("road",J22))),"Topography & Road Engineering","CHECK - map manually")))) -> Inadequate Design Capacity | BI22: =IF(A22="","",AND(UPPER(TRIM(BF22&""))="IDD",OR(TRIM(AN22&"")<>"",TRIM(AY22&"")<>"",TRIM(AZ22&"")<>""))) -> FALSE | BJ22: =IF(A22="","",IF(ISNUMBER(AZ22),AZ22,"CLIENT INPUT REQUIRED")) -> 46753 | BK22: =IF(A22="","",IF(BI22<>TRUE(),"No specific plan",IF(ISNUMBER(BJ22),IF(BJ22<'Exec Summary'!$C$4,"Resolved before Feb 2027","Resolved after Feb 2027"),"CLIENT INPUT REQUIRED"))) -> No specific plan
A23: 20 | B23: Al Fou'ah | C23: Al Fou'ah - Al Sajaa | D23: 24.359906 | E23: 55.787468 | F23: Medium | G23: Applicable with (AACM) | I23: No | J23: Absence of Drainage Network | K23: the accumulated water will be removed by a tanker and discharged at the nearest Wadi | AM23: No | AN23: Based on future design | AO23: Based on future design | AP23: Permenent | AQ23: No | AR23: - | AS23: No network | AT23: N/A | AU23: Based on future design | AV23: Based on future design | AW23: the information will be provided by end of next week | AX23: the information will be provided by end of next week | AY23: future project | AZ23: future project | BA23: future project | BB23: No | BC23: - | BD23: - | BE23: Not Started | BF23: AAI | BG23: =IF(A23="","",AND(TRIM(G23&"")<>"",UPPER(TRIM(G23&""))<>"NO")) -> TRUE | BH23: =IF(J23="","",IF(ISNUMBER(SEARCH("absen",J23)),"Absence of Drainage Network",IF(OR(ISNUMBER(SEARCH("design",J23)),ISNUMBER(SEARCH("capacity",J23))),"Inadequate Design Capacity",IF(OR(ISNUMBER(SEARCH("upgrade",J23)),ISNUMBER(SEARCH("network",J23)),ISNUMBER(SEARCH("topog",J23)),ISNUMBER(SEARCH("road",J23))),"Topography & Road Engineering","CHECK - map manually")))) -> Absence of Drainage Network | BI23: =IF(A23="","",AND(UPPER(TRIM(BF23&""))="IDD",OR(TRIM(AN23&"")<>"",TRIM(AY23&"")<>"",TRIM(AZ23&"")<>""))) -> FALSE | BJ23: =IF(A23="","",IF(ISNUMBER(AZ23),AZ23,"CLIENT INPUT REQUIRED")) -> CLIENT INPUT REQUIRED | BK23: =IF(A23="","",IF(BI23<>TRUE(),"No specific plan",IF(ISNUMBER(BJ23),IF(BJ23<'Exec Summary'!$C$4,"Resolved before Feb 2027","Resolved after Feb 2027"),"CLIENT INPUT REQUIRED"))) -> No specific plan
A24: 21 | B24: Al Fou'ah | C24: Abu 'Ubaidah Bin Al Jarrah St. Al Sajaa, Al Fou'ah | D24: 24.342632 | E24: 55.795046 | F24: High | G24: Applicable with (AACM) | I24: Yes | J24: Inadequate Design Capacity | K24: Existing or nearby drainage arrangements at Abu 'Ubaidah Bin Al Jarrah St. Al Sajaa, Al Fou'ah require pumping support during storm events, indicating insufficient conveyance/storage capacity for peak runoff. | AM24: Yes | AN24: Upgrade Network | AO24: Upgrade Network | AP24: Permenent | AQ24: No | AR24: - | AS24: 1:2 | AT24: 23mm depth for 24hr | AU24: 1:5 | AV24: 47mm depth for 24hr | AW24: the information will be provided by end of next week | AX24: the information will be provided by end of next week | AY24: 45658 | AZ24: 46357 | BA24: Implementation phase | BB24: Yes | BC24: 45824 | BD24: - | BE24: On Track | BF24: AAI | BG24: =IF(A24="","",AND(TRIM(G24&"")<>"",UPPER(TRIM(G24&""))<>"NO")) -> TRUE | BH24: =IF(J24="","",IF(ISNUMBER(SEARCH("absen",J24)),"Absence of Drainage Network",IF(OR(ISNUMBER(SEARCH("design",J24)),ISNUMBER(SEARCH("capacity",J24))),"Inadequate Design Capacity",IF(OR(ISNUMBER(SEARCH("upgrade",J24)),ISNUMBER(SEARCH("network",J24)),ISNUMBER(SEARCH("topog",J24)),ISNUMBER(SEARCH("road",J24))),"Topography & Road Engineering","CHECK - map manually")))) -> Inadequate Design Capacity | BI24: =IF(A24="","",AND(UPPER(TRIM(BF24&""))="IDD",OR(TRIM(AN24&"")<>"",TRIM(AY24&"")<>"",TRIM(AZ24&"")<>""))) -> FALSE | BJ24: =IF(A24="","",IF(ISNUMBER(AZ24),AZ24,"CLIENT INPUT REQUIRED")) -> 46357 | BK24: =IF(A24="","",IF(BI24<>TRUE(),"No specific plan",IF(ISNUMBER(BJ24),IF(BJ24<'Exec Summary'!$C$4,"Resolved before Feb 2027","Resolved after Feb 2027"),"CLIENT INPUT REQUIRED"))) -> No specific plan
A25: 22 | B25: Al Fou'ah | C25: Al Fouʹah St, Al Fou'ah - Al Raqiyah | D25: 24.334206 | E25: 55.792301 | F25: Medium | G25: Applicable with (AACM) | I25: Yes | J25: Inadequate Design Capacity | K25: Existing or nearby drainage arrangements at Al Fouʹah St, Al Fou'ah - Al Raqiyah require pumping support during storm events, indicating insufficient conveyance/storage capacity for peak runoff. Discharge point is nearest Wadi | AM25: No | AN25: Based on future design | AO25: Based on future design | AP25: Permenent | AQ25: No | AR25: - | AS25: 1:2 | AT25: 23mm depth for 24hr | AU25: Based on future design | AV25: Based on future design | AW25: the information will be provided by end of next week | AX25: the information will be provided by end of next week | AY25: future project | AZ25: future project | BA25: future project | BB25: No | BC25: - | BD25: - | BE25: Not Started | BF25: AAI | BG25: =IF(A25="","",AND(TRIM(G25&"")<>"",UPPER(TRIM(G25&""))<>"NO")) -> TRUE | BH25: =IF(J25="","",IF(ISNUMBER(SEARCH("absen",J25)),"Absence of Drainage Network",IF(OR(ISNUMBER(SEARCH("design",J25)),ISNUMBER(SEARCH("capacity",J25))),"Inadequate Design Capacity",IF(OR(ISNUMBER(SEARCH("upgrade",J25)),ISNUMBER(SEARCH("network",J25)),ISNUMBER(SEARCH("topog",J25)),ISNUMBER(SEARCH("road",J25))),"Topography & Road Engineering","CHECK - map manually")))) -> Inadequate Design Capacity | BI25: =IF(A25="","",AND(UPPER(TRIM(BF25&""))="IDD",OR(TRIM(AN25&"")<>"",TRIM(AY25&"")<>"",TRIM(AZ25&"")<>""))) -> FALSE | BJ25: =IF(A25="","",IF(ISNUMBER(AZ25),AZ25,"CLIENT INPUT REQUIRED")) -> CLIENT INPUT REQUIRED | BK25: =IF(A25="","",IF(BI25<>TRUE(),"No specific plan",IF(ISNUMBER(BJ25),IF(BJ25<'Exec Summary'!$C$4,"Resolved before Feb 2027","Resolved after Feb 2027"),"CLIENT INPUT REQUIRED"))) -> No specific plan
A26: 23 | B26: Al Hiyar | C26: Wadi Maad, Al Hiyar | D26: 24.6107 | E26: 55.756262 | F26: High | G26: Applicable with (AACM) | I26: Yes | J26: Inadequate Design Capacity | K26: Existing or nearby drainage arrangements at Wadi Maad, Al Hiyar require pumping support during storm events, indicating insufficient conveyance/storage capacity for peak runoff. Discharge point is nearest Wadi | P26: 2 | Z26: 10000 | AA26: 8 | AB26: 40000 | AM26: Yes | AN26: Upgrade Network | AO26: Upgrade Network | AP26: Permenent | AQ26: No | AR26: - | AS26: 1:2 | AT26: 23mm depth for 24hr | AU26: 1:5 | AV26: 47mm depth for 24hr | AW26: the information will be provided by end of next week | AX26: the information will be provided by end of next week | AY26: 45658 | AZ26: 46357 | BA26: Implementation phase | BB26: Yes | BC26: 46127 | BD26: - | BE26: On Track | BF26: AAI | BG26: =IF(A26="","",AND(TRIM(G26&"")<>"",UPPER(TRIM(G26&""))<>"NO")) -> TRUE | BH26: =IF(J26="","",IF(ISNUMBER(SEARCH("absen",J26)),"Absence of Drainage Network",IF(OR(ISNUMBER(SEARCH("design",J26)),ISNUMBER(SEARCH("capacity",J26))),"Inadequate Design Capacity",IF(OR(ISNUMBER(SEARCH("upgrade",J26)),ISNUMBER(SEARCH("network",J26)),ISNUMBER(SEARCH("topog",J26)),ISNUMBER(SEARCH("road",J26))),"Topography & Road Engineering","CHECK - map manually")))) -> Inadequate Design Capacity | BI26: =IF(A26="","",AND(UPPER(TRIM(BF26&""))="IDD",OR(TRIM(AN26&"")<>"",TRIM(AY26&"")<>"",TRIM(AZ26&"")<>""))) -> FALSE | BJ26: =IF(A26="","",IF(ISNUMBER(AZ26),AZ26,"CLIENT INPUT REQUIRED")) -> 46357 | BK26: =IF(A26="","",IF(BI26<>TRUE(),"No specific plan",IF(ISNUMBER(BJ26),IF(BJ26<'Exec Summary'!$C$4,"Resolved before Feb 2027","Resolved after Feb 2027"),"CLIENT INPUT REQUIRED"))) -> No specific plan
A27: 24 | B27: Al Hiyar | C27: Ramlat Al Hayer, Al Hiyar | D27: 24.603507 | E27: 55.759951 | F27: High | G27: Applicable with (AACM) | I27: No | J27: Absence of Drainage Network | K27: the accumulated water will be removed by a tanker and discharged at the nearest wadi | AM27: No | AN27: Based on future design | AO27: Based on future design | AP27: Permenent | AQ27: No | AR27: - | AS27: No network | AT27: N/A | AU27: Based on future design | AV27: Based on future design | AW27: the information will be provided by end of next week | AX27: the information will be provided by end of next week | AY27: future project | AZ27: future project | BA27: future project | BB27: No | BC27: - | BD27: - | BE27: Not Started | BF27: AAI | BG27: =IF(A27="","",AND(TRIM(G27&"")<>"",UPPER(TRIM(G27&""))<>"NO")) -> TRUE | BH27: =IF(J27="","",IF(ISNUMBER(SEARCH("absen",J27)),"Absence of Drainage Network",IF(OR(ISNUMBER(SEARCH("design",J27)),ISNUMBER(SEARCH("capacity",J27))),"Inadequate Design Capacity",IF(OR(ISNUMBER(SEARCH("upgrade",J27)),ISNUMBER(SEARCH("network",J27)),ISNUMBER(SEARCH("topog",J27)),ISNUMBER(SEARCH("road",J27))),"Topography & Road Engineering","CHECK - map manually")))) -> Absence of Drainage Network | BI27: =IF(A27="","",AND(UPPER(TRIM(BF27&""))="IDD",OR(TRIM(AN27&"")<>"",TRIM(AY27&"")<>"",TRIM(AZ27&"")<>""))) -> FALSE | BJ27: =IF(A27="","",IF(ISNUMBER(AZ27),AZ27,"CLIENT INPUT REQUIRED")) -> CLIENT INPUT REQUIRED | BK27: =IF(A27="","",IF(BI27<>TRUE(),"No specific plan",IF(ISNUMBER(BJ27),IF(BJ27<'Exec Summary'!$C$4,"Resolved before Feb 2027","Resolved after Feb 2027"),"CLIENT INPUT REQUIRED"))) -> No specific plan
A28: 25 | B28: Al Hiyar | C28: E20, Al Hiyar - Al Hayer 6 | D28: 24.582994 | E28: 55.73729 | F28: High | G28: Applicable with (AACM) | I28: No | J28: Absence of Drainage Network | K28: the accumulated water will be removed by a tanker and discharged at the nearest pond or another disposal location | AM28: No | AN28: Based on future design | AO28: Based on future design | AP28: Permenent | AQ28: No | AR28: - | AS28: No network | AT28: N/A | AU28: Based on future design | AV28: Based on future design | AW28: the information will be provided by end of next week | AX28: the information will be provided by end of next week | AY28: future project | AZ28: future project | BA28: future project | BB28: No | BC28: - | BD28: - | BE28: Not Started | BF28: AAI | BG28: =IF(A28="","",AND(TRIM(G28&"")<>"",UPPER(TRIM(G28&""))<>"NO")) -> TRUE | BH28: =IF(J28="","",IF(ISNUMBER(SEARCH("absen",J28)),"Absence of Drainage Network",IF(OR(ISNUMBER(SEARCH("design",J28)),ISNUMBER(SEARCH("capacity",J28))),"Inadequate Design Capacity",IF(OR(ISNUMBER(SEARCH("upgrade",J28)),ISNUMBER(SEARCH("network",J28)),ISNUMBER(SEARCH("topog",J28)),ISNUMBER(SEARCH("road",J28))),"Topography & Road Engineering","CHECK - map manually")))) -> Absence of Drainage Network | BI28: =IF(A28="","",AND(UPPER(TRIM(BF28&""))="IDD",OR(TRIM(AN28&"")<>"",TRIM(AY28&"")<>"",TRIM(AZ28&"")<>""))) -> FALSE | BJ28: =IF(A28="","",IF(ISNUMBER(AZ28),AZ28,"CLIENT INPUT REQUIRED")) -> CLIENT INPUT REQUIRED | BK28: =IF(A28="","",IF(BI28<>TRUE(),"No specific plan",IF(ISNUMBER(BJ28),IF(BJ28<'Exec Summary'!$C$4,"Resolved before Feb 2027","Resolved after Feb 2027"),"CLIENT INPUT REQUIRED"))) -> No specific plan
A29: 26 | B29: Al Hiyar | C29: Um Al Dakhan, Al Hiyar | D29: 24.524596 | E29: 55.552951 | F29: High | G29: Applicable with (AACM) | I29: No | J29: Absence of Drainage Network | K29: the accumulated water will be removed by a tanker and discharged at the nearest pond or another disposal location | AM29: Yes | AN29: Pond/Side slope protection | AO29: Pond/Side slope protection | AP29: Permenent | AQ29: No | AR29: - | AS29: 1:2 | AT29: 23mm depth for 24hr | AU29: 1:50 | AV29: 105mm depth for 24hr | AW29: the information will be provided by end of next week | AX29: the information will be provided by end of next week | AY29: 46327 | AZ29: 46722 | BA29: Design phase | BB29: Yes | BC29: - | BD29: - | BE29: Not Started | BF29: AAI | BG29: =IF(A29="","",AND(TRIM(G29&"")<>"",UPPER(TRIM(G29&""))<>"NO")) -> TRUE | BH29: =IF(J29="","",IF(ISNUMBER(SEARCH("absen",J29)),"Absence of Drainage Network",IF(OR(ISNUMBER(SEARCH("design",J29)),ISNUMBER(SEARCH("capacity",J29))),"Inadequate Design Capacity",IF(OR(ISNUMBER(SEARCH("upgrade",J29)),ISNUMBER(SEARCH("network",J29)),ISNUMBER(SEARCH("topog",J29)),ISNUMBER(SEARCH("road",J29))),"Topography & Road Engineering","CHECK - map manually")))) -> Absence of Drainage Network | BI29: =IF(A29="","",AND(UPPER(TRIM(BF29&""))="IDD",OR(TRIM(AN29&"")<>"",TRIM(AY29&"")<>"",TRIM(AZ29&"")<>""))) -> FALSE | BJ29: =IF(A29="","",IF(ISNUMBER(AZ29),AZ29,"CLIENT INPUT REQUIRED")) -> 46722 | BK29: =IF(A29="","",IF(BI29<>TRUE(),"No specific plan",IF(ISNUMBER(BJ29),IF(BJ29<'Exec Summary'!$C$4,"Resolved before Feb 2027","Resolved after Feb 2027"),"CLIENT INPUT REQUIRED"))) -> No specific plan
A30: 27 | B30: Al Hiyar | C30: Al Shansoobah, Al Hiyar | D30: 24.548806 | E30: 55.755433 | F30: High | G30: Applicable with (AACM) | I30: No | J30: Absence of Drainage Network | K30: the accumulated water will be removed by a tanker and discharged at the nearest pond or another disposal location | AM30: Yes | AN30: Pond/Side slope protection | AO30: Pond/Side slope protection | AP30: Permenent | AQ30: No | AR30: - | AS30: 1:2 | AT30: 23mm depth for 24hr | AU30: 1:50 | AV30: 105mm depth for 24hr | AW30: the information will be provided by end of next week | AX30: the information will be provided by end of next week | AY30: 46327 | AZ30: 46722 | BA30: Design phase | BB30: Yes | BC30: - | BD30: - | BE30: Not Started | BF30: AAI | BG30: =IF(A30="","",AND(TRIM(G30&"")<>"",UPPER(TRIM(G30&""))<>"NO")) -> TRUE | BH30: =IF(J30="","",IF(ISNUMBER(SEARCH("absen",J30)),"Absence of Drainage Network",IF(OR(ISNUMBER(SEARCH("design",J30)),ISNUMBER(SEARCH("capacity",J30))),"Inadequate Design Capacity",IF(OR(ISNUMBER(SEARCH("upgrade",J30)),ISNUMBER(SEARCH("network",J30)),ISNUMBER(SEARCH("topog",J30)),ISNUMBER(SEARCH("road",J30))),"Topography & Road Engineering","CHECK - map manually")))) -> Absence of Drainage Network | BI30: =IF(A30="","",AND(UPPER(TRIM(BF30&""))="IDD",OR(TRIM(AN30&"")<>"",TRIM(AY30&"")<>"",TRIM(AZ30&"")<>""))) -> FALSE | BJ30: =IF(A30="","",IF(ISNUMBER(AZ30),AZ30,"CLIENT INPUT REQUIRED")) -> 46722 | BK30: =IF(A30="","",IF(BI30<>TRUE(),"No specific plan",IF(ISNUMBER(BJ30),IF(BJ30<'Exec Summary'!$C$4,"Resolved before Feb 2027","Resolved after Feb 2027"),"CLIENT INPUT REQUIRED"))) -> No specific plan
A31: 28 | B31: Al Hiyar | C31: Al Shansoobah, Al Hiyar | D31: 24.572492 | E31: 55.747715 | F31: High | G31: Applicable with (AACM) | I31: Yes | J31: Inadequate Design Capacity | K31: Existing or nearby drainage arrangements at Al Shansoobah, Al Hiyar require pumping support during storm events, indicating insufficient conveyance/storage capacity for peak runoff. | AM31: Yes | AN31: Pond/Side slope protection | AO31: Pond/Side slope protection | AP31: Permenent | AQ31: No | AR31: - | AS31: 1:2 | AT31: 23mm depth for 24hr | AU31: 1:50 | AV31: 105mm depth for 24hr | AW31: the information will be provided by end of next week | AX31: the information will be provided by end of next week | AY31: 46327 | AZ31: 46722 | BA31: Design phase | BB31: Yes | BC31: - | BD31: - | BE31: Not Started | BF31: AAI | BG31: =IF(A31="","",AND(TRIM(G31&"")<>"",UPPER(TRIM(G31&""))<>"NO")) -> TRUE | BH31: =IF(J31="","",IF(ISNUMBER(SEARCH("absen",J31)),"Absence of Drainage Network",IF(OR(ISNUMBER(SEARCH("design",J31)),ISNUMBER(SEARCH("capacity",J31))),"Inadequate Design Capacity",IF(OR(ISNUMBER(SEARCH("upgrade",J31)),ISNUMBER(SEARCH("network",J31)),ISNUMBER(SEARCH("topog",J31)),ISNUMBER(SEARCH("road",J31))),"Topography & Road Engineering","CHECK - map manually")))) -> Inadequate Design Capacity | BI31: =IF(A31="","",AND(UPPER(TRIM(BF31&""))="IDD",OR(TRIM(AN31&"")<>"",TRIM(AY31&"")<>"",TRIM(AZ31&"")<>""))) -> FALSE | BJ31: =IF(A31="","",IF(ISNUMBER(AZ31),AZ31,"CLIENT INPUT REQUIRED")) -> 46722 | BK31: =IF(A31="","",IF(BI31<>TRUE(),"No specific plan",IF(ISNUMBER(BJ31),IF(BJ31<'Exec Summary'!$C$4,"Resolved before Feb 2027","Resolved after Feb 2027"),"CLIENT INPUT REQUIRED"))) -> No specific plan
A32: 29 | B32: Al Hiyar | C32: 36 Wadi At Tabnah St, Al Hiyar - Ramlat Al Hayer | D32: 24.588918 | E32: 55.744243 | F32: High | G32: Applicable with (AACM) | I32: No | J32: Absence of Drainage Network | K32: the accumulated water will be removed by a tanker and discharged at the nearest pond or another disposal location | AM32: Yes | AN32: New Network | AO32: New Network | AP32: Permenent | AQ32: No | AR32: - | AS32: 1:2 | AT32: 23mm depth for 24hr | AU32: 1:5 | AV32: 47mm depth for 24hr | AW32: the information will be provided by end of next week | AX32: the information will be provided by end of next week | AY32: Ongoing | AZ32: Ongoing | BA32: Design phase | BB32: Yes | BC32: - | BD32: - | BE32: Not Started | BF32: AAI | BG32: =IF(A32="","",AND(TRIM(G32&"")<>"",UPPER(TRIM(G32&""))<>"NO")) -> TRUE | BH32: =IF(J32="","",IF(ISNUMBER(SEARCH("absen",J32)),"Absence of Drainage Network",IF(OR(ISNUMBER(SEARCH("design",J32)),ISNUMBER(SEARCH("capacity",J32))),"Inadequate Design Capacity",IF(OR(ISNUMBER(SEARCH("upgrade",J32)),ISNUMBER(SEARCH("network",J32)),ISNUMBER(SEARCH("topog",J32)),ISNUMBER(SEARCH("road",J32))),"Topography & Road Engineering","CHECK - map manually")))) -> Absence of Drainage Network | BI32: =IF(A32="","",AND(UPPER(TRIM(BF32&""))="IDD",OR(TRIM(AN32&"")<>"",TRIM(AY32&"")<>"",TRIM(AZ32&"")<>""))) -> FALSE | BJ32: =IF(A32="","",IF(ISNUMBER(AZ32),AZ32,"CLIENT INPUT REQUIRED")) -> CLIENT INPUT REQUIRED | BK32: =IF(A32="","",IF(BI32<>TRUE(),"No specific plan",IF(ISNUMBER(BJ32),IF(BJ32<'Exec Summary'!$C$4,"Resolved before Feb 2027","Resolved after Feb 2027"),"CLIENT INPUT REQUIRED"))) -> No specific plan
